<?xml version="1.0"?>
<robot xmlns:xacro="http://ros.org/wiki/xacro">

  <xacro:include filename="$(find ezbot-v2)/description/roller/roller.transmission.xacro"/>
  <xacro:include filename="$(find ezbot-v2)/description/roller/roller.gazebo.xacro"/>
  
  <xacro:macro name="roller_v0" params="prefix parent *joint_origin *joint_axis">
	<joint name="${prefix}_roller_joint" type="continuous">
	  <xacro:insert_block name="joint_origin"/>
	  <parent link="${parent}"/>
	  <child link="${prefix}_roller_link"/>
	  <xacro:insert_block name="joint_axis"/>
    <!--
      Setting friction too high (1.0 tested) result in weird movement and behavior 
    -->
    <dynamics damping="0.0" friction="0.01"/>
	</joint>

	<link name="${prefix}_roller_link">
	  
    <visual>
      <geometry>
        <mesh filename="file://$(find ezbot-v2)/meshes/DAE/roller/roller.dae"/>
      </geometry>
	  </visual>
	  
    <collision>
      <geometry>
        <mesh filename="file://$(find ezbot-v2)/meshes/STL/roller/roller.stl"/>
      </geometry>
	  </collision>
	  <inertial>
      <origin xyz="0.0 0.0 0.0"/>
      <mass value="0.009"/>
      <inertia ixx="0.000001257" ixy="0" ixz="0" iyy="0.000000342" iyz="0" izz="0.000001257"/>
	  </inertial>
	</link>

  <gazebo reference="${prefix}_roller_link">
    <mu1>1.9</mu1>
    <mu2>1.9</mu2>
    <kp>1e15</kp>
    <kd>1e13</kd>
    <collision>
        <surface>
            <contact>
            <ode>
                <max_vel>10</max_vel>
                <min_depth>0.001</min_depth>
            </ode>
            </contact>
        </surface>
    </collision>
  </gazebo>


  </xacro:macro>
  
</robot>
